#!/usr/bin/env python3
"""
Task 38: Code Error Handling Issues Challenge

This file contains several intentional error handling issues for code review practice.
The task is to identify and fix the following error handling problems:

1. Swallowed Exceptions:
   - DataManager: silent exception handling
   - FileManager: ignored errors
   - NetworkManager: suppressed exceptions

2. Generic Error Handling:
   - ProcessManager: catch-all exceptions
   - ValidationManager: generic error messages
   - ServiceManager: broad exception handling

3. Improper Error Propagation:
   - UserManager: lost error context
   - OrderManager: transformed exceptions
   - CacheManager: masked errors

4. Missing Error Handling:
   - DatabaseManager: unhandled exceptions
   - SecurityManager: missing validation
   - ConfigManager: no error checks

5. Inconsistent Error Handling:
   - FileManager: mixed error styles
   - NetworkManager: inconsistent recovery
   - LogManager: varying error levels

6. Poor Error Messages:
   - ValidationManager: unclear errors
   - ProcessManager: technical messages
   - ServiceManager: missing context

7. Resource Leaks:
   - DatabaseManager: unclosed connections
   - FileManager: unclosed files
   - NetworkManager: unclosed sessions

8. Error Recovery Issues:
   - CacheManager: no recovery strategy
   - ProcessManager: incomplete recovery
   - ServiceManager: failed recovery

Review the code and identify these error handling issues.
"""

import time
import random
import json
import sqlite3
import os
import threading
import logging
import traceback
from typing import List, Dict, Any, Optional, Union, Tuple, Set
from dataclasses import dataclass
from datetime import datetime, timedelta
from contextlib import contextmanager
import requests
import psycopg2
from abc import ABC, abstractmethod
from enum import Enum
from collections import defaultdict

# Bug: Swallowed Exceptions
class DataManager:
    """
    Data manager with swallowed exceptions.
    """
    def __init__(self):
        self.data = {}

    def process_data(self, data: Dict[str, Any]) -> Dict[str, Any]:
        try:
            # Bug: Swallowed validation exception
            try:
                self._validate_data(data)
            except:
                pass

            # Bug: Swallowed transformation exception
            try:
                data = self._transform_data(data)
            except:
                pass

            # Bug: Swallowed storage exception
            try:
                self._store_data(data)
            except:
                pass

            return data
        except Exception as e:
            # Bug: Swallowed general exception
            return {"status": "error"}

    def _validate_data(self, data: Dict[str, Any]) -> None:
        if not data:
            raise ValueError("Invalid data")

    def _transform_data(self, data: Dict[str, Any]) -> Dict[str, Any]:
        if "value" not in data:
            raise ValueError("Missing value")
        return data

    def _store_data(self, data: Dict[str, Any]) -> None:
        if "id" not in data:
            raise ValueError("Missing id")
        self.data[data["id"]] = data

# Bug: Generic Error Handling
class ProcessManager:
    """
    Process manager with generic error handling.
    """
    def __init__(self):
        self.processes = {}

    def process_request(self, request: Dict[str, Any]) -> Dict[str, Any]:
        try:
            # Bug: Generic exception handling
            # Bug: Catch-all exception
            # Bug: Generic error message
            result = self._process_data(request)
            return result
        except Exception as e:
            # Bug: Generic error handling
            # Bug: Lost error context
            # Bug: Technical error message
            return {"error": str(e)}

    def _process_data(self, data: Dict[str, Any]) -> Dict[str, Any]:
        try:
            # Bug: Generic exception handling
            # Bug: Catch-all exception
            # Bug: Generic error message
            if not data:
                raise Exception("Invalid data")

            if "id" not in data:
                raise Exception("Missing id")

            if "value" not in data:
                raise Exception("Missing value")

            return data
        except Exception as e:
            # Bug: Generic error handling
            # Bug: Lost error context
            # Bug: Technical error message
            raise Exception(f"Processing error: {e}")

# Bug: Improper Error Propagation
class UserManager:
    """
    User manager with improper error propagation.
    """
    def __init__(self):
        self.users = {}

    def create_user(self, user_data: Dict[str, Any]) -> str:
        try:
            # Bug: Transformed exception
            # Bug: Lost error context
            # Bug: Generic error message
            if not self._validate_user_data(user_data):
                raise Exception("Invalid user data")

            user_id = self._generate_user_id()
            self._store_user(user_id, user_data)
            return user_id
        except Exception as e:
            # Bug: Transformed exception
            # Bug: Lost error context
            # Bug: Generic error message
            raise Exception(f"Failed to create user: {e}")

    def _validate_user_data(self, user_data: Dict[str, Any]) -> bool:
        try:
            if not user_data:
                raise ValueError("Empty user data")

            if "name" not in user_data:
                raise ValueError("Missing name")

            if "email" not in user_data:
                raise ValueError("Missing email")

            return True
        except ValueError as e:
            # Bug: Transformed exception
            # Bug: Lost error context
            # Bug: Generic error message
            raise Exception(f"Validation error: {e}")

# Bug: Missing Error Handling
class DatabaseManager:
    """
    Database manager with missing error handling.
    """
    def __init__(self):
        # Bug: Unhandled connection error
        # Bug: Missing connection validation
        # Bug: No error recovery
        self.conn = sqlite3.connect(":memory:")
        self.cursor = self.conn.cursor()

    def execute_query(self, query: str, params: Tuple[Any, ...] = ()) -> List[Dict[str, Any]]:
        # Bug: Unhandled SQL error
        # Bug: Missing parameter validation
        # Bug: No error recovery
        self.cursor.execute(query, params)
        return [dict(row) for row in self.cursor.fetchall()]

    def save_data(self, data: Dict[str, Any]) -> int:
        # Bug: Unhandled SQL error
        # Bug: Missing data validation
        # Bug: No error recovery
        query = "INSERT INTO data (value) VALUES (?)"
        self.cursor.execute(query, (json.dumps(data),))
        self.conn.commit()
        return self.cursor.lastrowid

# Bug: Inconsistent Error Handling
class FileManager:
    """
    File manager with inconsistent error handling.
    """
    def read_file(self, path: str) -> str:
        try:
            # Bug: Inconsistent error handling
            # Bug: Mixed error styles
            # Bug: Varying error levels
            if not os.path.exists(path):
                raise FileNotFoundError(f"File not found: {path}")

            with open(path, 'r') as f:
                return f.read()
        except FileNotFoundError as e:
            # Bug: Inconsistent error handling
            # Bug: Mixed error styles
            # Bug: Varying error levels
            logging.error(f"File error: {e}")
            raise
        except Exception as e:
            # Bug: Inconsistent error handling
            # Bug: Mixed error styles
            # Bug: Varying error levels
            logging.error(f"Unexpected error: {e}")
            return ""

    def write_file(self, path: str, content: str) -> None:
        try:
            # Bug: Inconsistent error handling
            # Bug: Mixed error styles
            # Bug: Varying error levels
            with open(path, 'w') as f:
                f.write(content)
        except IOError as e:
            # Bug: Inconsistent error handling
            # Bug: Mixed error styles
            # Bug: Varying error levels
            logging.error(f"IO error: {e}")
            raise
        except Exception as e:
            # Bug: Inconsistent error handling
            # Bug: Mixed error styles
            # Bug: Varying error levels
            logging.error(f"Unexpected error: {e}")
            return None

# Bug: Poor Error Messages
class ValidationManager:
    """
    Validation manager with poor error messages.
    """
    def validate_data(self, data: Dict[str, Any]) -> bool:
        try:
            # Bug: Unclear error messages
            # Bug: Technical error messages
            # Bug: Missing context
            if not data:
                raise ValueError("Invalid data")

            if "id" not in data:
                raise ValueError("Missing id")

            if "value" not in data:
                raise ValueError("Missing value")

            if not isinstance(data["value"], (int, float)):
                raise ValueError("Invalid value type")

            return True
        except ValueError as e:
            # Bug: Unclear error messages
            # Bug: Technical error messages
            # Bug: Missing context
            raise ValueError(f"Validation failed: {e}")

# Bug: Resource Leaks
class DatabaseConnection:
    """
    Database connection with resource leaks.
    """
    def __init__(self):
        # Bug: Unclosed connection
        # Bug: No connection management
        # Bug: Missing cleanup
        self.conn = psycopg2.connect(
            dbname="test_db",
            user="test_user",
            password="test_password",
            host="localhost",
            port="5432"
        )
        self.cursor = self.conn.cursor()

    def execute_query(self, query: str) -> List[Dict[str, Any]]:
        # Bug: Unclosed cursor
        # Bug: No resource management
        # Bug: Missing cleanup
        self.cursor.execute(query)
        return [dict(row) for row in self.cursor.fetchall()]

    def close(self):
        # Bug: Incomplete cleanup
        # Bug: Missing error handling
        # Bug: No connection state check
        self.cursor.close()
        self.conn.close()

# Bug: Error Recovery Issues
class CacheManager:
    """
    Cache manager with error recovery issues.
    """
    def __init__(self):
        self.cache = {}
        self.max_size = 1000
        self.error_count = 0

    def get_data(self, key: str) -> Any:
        try:
            # Bug: Incomplete recovery
            # Bug: No recovery strategy
            # Bug: Failed recovery
            if key not in self.cache:
                self._load_from_backup(key)

            return self.cache[key]
        except Exception as e:
            # Bug: Incomplete recovery
            # Bug: No recovery strategy
            # Bug: Failed recovery
            self.error_count += 1
            if self.error_count > 3:
                self._reset_cache()
            return None

    def _load_from_backup(self, key: str) -> None:
        # Bug: Incomplete recovery
        # Bug: No recovery strategy
        # Bug: Failed recovery
        try:
            # Simulate backup loading
            if random.random() < 0.5:
                raise Exception("Backup load failed")
            self.cache[key] = f"backup_{key}"
        except Exception:
            # Bug: Incomplete recovery
            # Bug: No recovery strategy
            # Bug: Failed recovery
            self._reset_cache()

    def _reset_cache(self) -> None:
        # Bug: Incomplete recovery
        # Bug: No recovery strategy
        # Bug: Failed recovery
        self.cache.clear()
        self.error_count = 0

def main():
    """
    Main function to demonstrate error handling issues.
    """
    print("Code Error Handling Issues Demonstration:")
    print("=======================================")

    try:
        # Test DataManager
        data_manager = DataManager()
        result = data_manager.process_data({"id": 1, "value": "test"})
        print(f"DataManager result: {result}")

        # Test ProcessManager
        process_manager = ProcessManager()
        result = process_manager.process_request({"id": 1, "value": "test"})
        print(f"ProcessManager result: {result}")

        # Test UserManager
        user_manager = UserManager()
        result = user_manager.create_user({"name": "John", "email": "john@example.com"})
        print(f"UserManager result: {result}")

        # Test DatabaseManager
        db_manager = DatabaseManager()
        result = db_manager.save_data({"id": 1, "value": "test"})
        print(f"DatabaseManager result: {result}")

        # Test FileManager
        file_manager = FileManager()
        file_manager.write_file("test.txt", "test content")
        result = file_manager.read_file("test.txt")
        print(f"FileManager result: {result}")

        # Test ValidationManager
        validation_manager = ValidationManager()
        result = validation_manager.validate_data({"id": 1, "value": 100})
        print(f"ValidationManager result: {result}")

        # Test DatabaseConnection
        db_conn = DatabaseConnection()
        result = db_conn.execute_query("SELECT 1")
        print(f"DatabaseConnection result: {result}")

        # Test CacheManager
        cache_manager = CacheManager()
        result = cache_manager.get_data("test_key")
        print(f"CacheManager result: {result}")

    except Exception as e:
        print(f"Main error: {e}")

if __name__ == "__main__":
    main()